// Uncomment the code below and write your tests
import {
  throwError,
  throwCustomError,
  resolveValue,
  MyAwesomeError,
  rejectCustomError,
} from './index';

describe('resolveValue', () => {
  test('should resolve provided value', async () => {
    const value = 'value';
    await expect(resolveValue(value)).resolves.toBe(value);
  });
});

describe('throwError', () => {
  test('should throw error with provided message', () => {
    const message = 'Error, please try again later';
    expect(() => throwError(message)).toThrowError(new Error(message));
  });

  test('should throw error with default message if message is not provided', () => {
    expect(() => throwError()).toThrowError(new Error('Oops!'));
  });
});

describe('throwCustomError', () => {
  test('should throw custom error', () => {
    expect(() => throwCustomError()).toThrowError(MyAwesomeError);
  });
});

describe('rejectCustomError', () => {
  test('should reject custom error', async () => {
    await expect(rejectCustomError()).rejects.toThrowError(MyAwesomeError);
  });
});
